Using GPU
Regenerating dataset...
Traceback (most recent call last):
  File "/home/marcus/programming/gnn-protein-dna/lib/python3.10/site-packages/pandas/core/indexes/base.py", line 3805, in get_loc
    return self._engine.get_loc(casted_key)
  File "index.pyx", line 167, in pandas._libs.index.IndexEngine.get_loc
  File "index.pyx", line 196, in pandas._libs.index.IndexEngine.get_loc
  File "pandas/_libs/hashtable_class_helper.pxi", line 7081, in pandas._libs.hashtable.PyObjectHashTable.get_item
  File "pandas/_libs/hashtable_class_helper.pxi", line 7089, in pandas._libs.hashtable.PyObjectHashTable.get_item
KeyError: 'log_K_d'

The above exception was the direct cause of the following exception:

Traceback (most recent call last):
  File "/home/marcus/programming/structural_binding_affinity_predictions_using_gnn/src/train.py", line 263, in <module>
    main()
  File "/home/marcus/programming/structural_binding_affinity_predictions_using_gnn/src/train.py", line 258, in main
    trainer = Trainer(config, device)
  File "/home/marcus/programming/structural_binding_affinity_predictions_using_gnn/src/train.py", line 55, in __init__
    self.train_dataset = ProteinDNADataset(data_dir, cfg=config)
  File "/home/marcus/programming/structural_binding_affinity_predictions_using_gnn/src/proteinDNADataset.py", line 47, in __init__
    self.labels = self.load_labels()
  File "/home/marcus/programming/structural_binding_affinity_predictions_using_gnn/src/proteinDNADataset.py", line 133, in load_labels
    log_K_d = torch.tensor(row["log_K_d"], dtype=torch.float32)
  File "/home/marcus/programming/gnn-protein-dna/lib/python3.10/site-packages/pandas/core/series.py", line 1121, in __getitem__
    return self._get_value(key)
  File "/home/marcus/programming/gnn-protein-dna/lib/python3.10/site-packages/pandas/core/series.py", line 1237, in _get_value
    loc = self.index.get_loc(label)
  File "/home/marcus/programming/gnn-protein-dna/lib/python3.10/site-packages/pandas/core/indexes/base.py", line 3812, in get_loc
    raise KeyError(key) from err
KeyError: 'log_K_d'
Traceback (most recent call last):
  File "/home/marcus/programming/gnn-protein-dna/lib/python3.10/site-packages/pandas/core/indexes/base.py", line 3805, in get_loc
    return self._engine.get_loc(casted_key)
  File "index.pyx", line 167, in pandas._libs.index.IndexEngine.get_loc
  File "index.pyx", line 196, in pandas._libs.index.IndexEngine.get_loc
  File "pandas/_libs/hashtable_class_helper.pxi", line 7081, in pandas._libs.hashtable.PyObjectHashTable.get_item
  File "pandas/_libs/hashtable_class_helper.pxi", line 7089, in pandas._libs.hashtable.PyObjectHashTable.get_item
KeyError: 'log_K_d'

The above exception was the direct cause of the following exception:

Traceback (most recent call last):
  File "/home/marcus/programming/structural_binding_affinity_predictions_using_gnn/src/train.py", line 263, in <module>
    main()
  File "/home/marcus/programming/structural_binding_affinity_predictions_using_gnn/src/train.py", line 258, in main
    trainer = Trainer(config, device)
  File "/home/marcus/programming/structural_binding_affinity_predictions_using_gnn/src/train.py", line 55, in __init__
    self.train_dataset = ProteinDNADataset(data_dir, cfg=config)
  File "/home/marcus/programming/structural_binding_affinity_predictions_using_gnn/src/proteinDNADataset.py", line 47, in __init__
    self.labels = self.load_labels()
  File "/home/marcus/programming/structural_binding_affinity_predictions_using_gnn/src/proteinDNADataset.py", line 133, in load_labels
    log_K_d = torch.tensor(row["log_K_d"], dtype=torch.float32)
  File "/home/marcus/programming/gnn-protein-dna/lib/python3.10/site-packages/pandas/core/series.py", line 1121, in __getitem__
    return self._get_value(key)
  File "/home/marcus/programming/gnn-protein-dna/lib/python3.10/site-packages/pandas/core/series.py", line 1237, in _get_value
    loc = self.index.get_loc(label)
  File "/home/marcus/programming/gnn-protein-dna/lib/python3.10/site-packages/pandas/core/indexes/base.py", line 3812, in get_loc
    raise KeyError(key) from err
KeyError: 'log_K_d'
